<mujoco>
    <asset>
        <material name="target_material" rgba="1 1 1 1" />
    </asset>
    <asset>
        <material name="wheel_material" rgba="0 0 0 1" reflectance="0" shininess="0" emission="0" specular="0.1" />
    </asset>
    <asset>
        <material name="mainCar_chassis_material" rgba="0.8 0.102 0.063 1" reflectance="0" shininess="1" emission="0.0" specular="0.0" />
    </asset>
    <asset>
        <texture name="sky_texture" type="skybox" file="assets/Wispy_Sky-Night_03-512x512.png" />
        <texture name="wall_texture" type="2d" file="assets/Fuzzy_Sky-Night_01-512x512.png" />
        <material name="wall_material" rgba="1 1 1 0.000001" />
        <texture name="ground_texture" type="2d" file="assets/ground.png" />
        <material name="ground_material" texture="ground_texture" texrepeat="25 25" />
    </asset>
    <worldbody>
        <geom name="ground_bottom" type="plane" size="10.0 10.0 2.5" material="ground_material" friction="1.0 0.005 0.0001" />
        <geom name="ground_left" type="box" size="2.5 10.0 10.0" pos="-12.5 0 10.0" material="wall_material" />
        <geom name="ground_right" type="box" size="2.5 10.0 10.0" pos="12.5 0 10.0" material="wall_material" />
        <geom name="ground_front" type="box" size="10.0 2.5 10.0" pos="0 12.5 10.0" material="wall_material" />
        <geom name="ground_back" type="box" size="10.0 2.5 10.0" pos="0 -12.5 10.0" material="wall_material" />
        <geom name="ground_top" type="box" size="10.0 10.0 2.5" pos="0 0 20" rgba="0 0 0 0" />
        <light dir="0 0 -1" pos="0 0 100" diffuse="1 1 1" castshadow="true" />
        <light dir="0.6963106238227914 -0.6963106238227914 0.17407765595569785" pos="-10.0 10.0 2.5" diffuse="0.3 0.3 0.3" castshadow="false" />
        <light dir="-0.6963106238227914 -0.6963106238227914 0.17407765595569785" pos="10.0 10.0 2.5" diffuse="0.3 0.3 0.3" castshadow="false" />
        <light dir="0.6963106238227914 0.6963106238227914 0.17407765595569785" pos="-10.0 -10.0 2.5" diffuse="0.3 0.3 0.3" castshadow="false" />
        <light dir="-0.6963106238227914 0.6963106238227914 0.17407765595569785" pos="10.0 -10.0 2.5" diffuse="0.3 0.3 0.3" castshadow="false" />
        <camera name="TopDownCam" pos="0 0 9.999999999999998" euler="0 0 -90" fovy="90" />
        <body name="mainCar" pos="0 0 2">
            <freejoint />
            <site name="mainCar_center" type="cylinder" size="0.1 0.001" />
            <body name="mainCar_front_lights" pos="1.0 0 0" />
            <body name="mainCar_chassis">
                <geom name="mainCar_chassis_geom" material="mainCar_chassis_material" type="box" size="1.0 0.5 0.125" mass="1500" />
                <site name="mainCar_chassis_site" type="box" size="1.0 0.5 0.125" rgba="0 0 0 0" />
                <body name="mainCar_wheel1" pos="0.6 -0.5 -0.0625" zaxis="0 1 0">
                    <joint name="mainCar_wheel1_joint_steer" type="hinge" axis="0 1 0" limited="true" range="-45 45" />
                    <joint name="mainCar_wheel1_joint_roll" />
                    <geom type="cylinder" size="0.3 0.1" material="wheel_material" mass="30" friction="1 0.001 0.001" />
                </body>
                <body name="mainCar_wheel2" pos="0.6 0.5 -0.0625" zaxis="0 1 0">
                    <joint name="mainCar_wheel2_joint_steer" type="hinge" axis="0 1 0" limited="true" range="-45 45" />
                    <joint name="mainCar_wheel2_joint_roll" />
                    <geom type="cylinder" size="0.3 0.1" material="wheel_material" mass="30" friction="1 0.001 0.001" />
                </body>
                <body name="mainCar_wheel3" pos="-0.6 -0.5 -0.0625" zaxis="0 1 0">
                    <joint name="mainCar_wheel3_joint_roll" />
                    <geom type="cylinder" size="0.3 0.1" material="wheel_material" mass="30" friction="1 0.001 0.001" />
                </body>
                <body name="mainCar_wheel4" pos="-0.6 0.5 -0.0625" zaxis="0 1 0">
                    <joint name="mainCar_wheel4_joint_roll" />
                    <geom type="cylinder" size="0.3 0.1" material="wheel_material" mass="30" friction="1 0.001 0.001" />
                </body>
            </body>
            <site name="mainCar_sensor_site_0" type="sphere" size="1e-06 1e-06" pos="1.001 0.5005 0.0" zaxis="1.001 0.5005 0.0" />
            <site name="mainCar_sensor_site_1" type="sphere" size="1e-06 1e-06" pos="1.001 0.0 0.0" zaxis="1.001 0.0 0.0" />
            <site name="mainCar_sensor_site_2" type="sphere" size="1e-06 1e-06" pos="1.001 -0.5005 0.0" zaxis="1.001 -0.5005 0.0" />
            <site name="mainCar_sensor_site_3" type="sphere" size="1e-06 1e-06" pos="-1.001 0.5005 0.0" zaxis="-1.001 0.5005 0.0" />
            <site name="mainCar_sensor_site_4" type="sphere" size="1e-06 1e-06" pos="-1.001 0.0 0.0" zaxis="-1.001 0.0 0.0" />
            <site name="mainCar_sensor_site_5" type="sphere" size="1e-06 1e-06" pos="-1.001 -0.5005 0.0" zaxis="-1.001 -0.5005 0.0" />
            <site name="mainCar_sensor_site_6" type="sphere" size="1e-06 1e-06" pos="0.0 0.5005 0.0" zaxis="0.0 0.5005 0.0" />
            <site name="mainCar_sensor_site_7" type="sphere" size="1e-06 1e-06" pos="0.0 -0.5005 0.0" zaxis="0.0 -0.5005 0.0" />
        </body>
        <body name="target_space" pos="5 5 0">
            <site name="parking_spot_center" type="cylinder" size="0.1 0.001" material="target_material" />
            <geom name="parking_area" type="box" size="1.4 0.85 0.001" pos="0 0 0" friction="1.0 0.005 0.0001" material="target_material" rgba="0 0 0 0" />
            <geom name="parking_edge_1" type="box" size="0.1 0.85 0.001" pos="1.2999999999999998 0 0" friction="1.0 0.005 0.0001" material="target_material" />
            <geom name="parking_edge_2" type="box" size="1.4 0.1 0.001" pos="0 0.75 0" friction="1.0 0.005 0.0001" material="target_material" />
            <geom name="parking_edge_3" type="box" size="1.4 0.1 0.001" pos="0 -0.75 0" friction="1.0 0.005 0.0001" material="target_material" />
            <geom name="parking_edge_4" type="box" size="0.1 0.85 0.001" pos="-1.2999999999999998 0 0" friction="1.0 0.005 0.0001" material="target_material" />
        </body>
    </worldbody>
    <tendon>
        <fixed name="mainCar_back_wheels_tendon">
            <joint joint="mainCar_wheel3_joint_roll" coef="1000" />
            <joint joint="mainCar_wheel4_joint_roll" coef="1000" />
        </fixed>
    </tendon>
    <actuator>
        <motor name="mainCar_engine_power" tendon="mainCar_back_wheels_tendon" ctrlrange="-1 1" />
        <position name="mainCar_wheel1_angle" joint="mainCar_wheel1_joint_steer" kp="1000" ctrlrange="-0.7853981633974483 0.7853981633974483" />
        <position name="mainCar_wheel2_angle" joint="mainCar_wheel2_joint_steer" kp="1000" ctrlrange="-0.7853981633974483 0.7853981633974483" />
    </actuator>
    <sensor>
        <touch name="mainCar_chassis_touch_sensor" site="mainCar_chassis_site" cutoff="5" />
        <velocimeter name="mainCar_speed_sensor" site="mainCar_center" cutoff="10" />
        <framepos name="mainCar_posGlobal_sensor" objtype="site" objname="mainCar_center" />
        <framepos name="mainCar_posTarget_sensor" objtype="site" objname="mainCar_center" reftype="site" refname="parking_spot_center" />
        <rangefinder name="mainCar_sensor_0" site="mainCar_sensor_site_0" cutoff="5" />
        <rangefinder name="mainCar_sensor_1" site="mainCar_sensor_site_1" cutoff="5" />
        <rangefinder name="mainCar_sensor_2" site="mainCar_sensor_site_2" cutoff="5" />
        <rangefinder name="mainCar_sensor_3" site="mainCar_sensor_site_3" cutoff="5" />
        <rangefinder name="mainCar_sensor_4" site="mainCar_sensor_site_4" cutoff="5" />
        <rangefinder name="mainCar_sensor_5" site="mainCar_sensor_site_5" cutoff="5" />
        <rangefinder name="mainCar_sensor_6" site="mainCar_sensor_site_6" cutoff="5" />
        <rangefinder name="mainCar_sensor_7" site="mainCar_sensor_site_7" cutoff="5" />
    </sensor>
</mujoco>