<mujoco>
    <asset>
        <material name="wheel_material" rgba="0 0 0 1" reflectance="0" shininess="0" emission="0" specular="0.1" />
    </asset>
    <asset>
        <material name="car1_chassis_material" rgba="0.8 0.102 0.063 1" reflectance="0" shininess="1" emission="0.0" specular="0.0" />
    </asset>
    <asset>
        <texture name="sky_texture" type="skybox" file="assets/Wispy_Sky-Night_03-512x512.png" />
        <texture name="wall_texture" type="2d" file="assets/Fuzzy_Sky-Night_01-512x512.png" />
        <material name="wall_material" rgba="0 0 0 0" />
        <texture name="ground_texture" type="2d" file="assets/ground.png" />
        <material name="ground_material" texture="ground_texture" texrepeat="25 25" />
    </asset>
    <worldbody>
        <geom name="ground_bottom" type="plane" size="25.0 25.0 0.5" material="ground_material" friction="1.0 0.005 0.0001" />
        <geom name="ground_left" type="box" size="0.5 25.0 10.0" pos="-25.5 0 10.0" material="wall_material" />
        <geom name="ground_right" type="box" size="0.5 25.0 10.0" pos="25.5 0 10.0" material="wall_material" />
        <geom name="ground_front" type="box" size="25.0 0.5 10.0" pos="0 25.5 10.0" material="wall_material" />
        <geom name="ground_back" type="box" size="25.0 0.5 10.0" pos="0 -25.5 10.0" material="wall_material" />
        <geom name="ground_top" type="box" size="25.0 25.0 0.5" pos="0 0 20" material="wall_material" />
        <light dir="0 0 -1" pos="0 0 100" diffuse="1 1 1" castshadow="true" />
        <camera name="TopDownCam" pos="0 0 24.999999999999996" euler="0 0 -90" fovy="90" />
        <body name="car1" pos="0 0 2">
            <freejoint />
            <body name="car1_front_lights" pos="1.0 0 0" />
            <body name="car1_chassis">
                <geom name="car1_chassis_geom" material="car1_chassis_material" type="box" size="1.0 0.5 0.125" mass="1500" />
                <body name="car1_wheel1" pos="0.6 -0.5 -0.0625" zaxis="0 1 0">
                    <joint name="car1_wheel1_joint_steer" type="hinge" axis="0 1 0" limited="true" range="-45 45" />
                    <joint name="car1_wheel1_joint_roll" />
                    <geom type="cylinder" size="0.3 0.1" material="wheel_material" mass="30" friction="1 0.001 0.001" />
                </body>
                <body name="car1_wheel2" pos="0.6 0.5 -0.0625" zaxis="0 1 0">
                    <joint name="car1_wheel2_joint_steer" type="hinge" axis="0 1 0" limited="true" range="-45 45" />
                    <joint name="car1_wheel2_joint_roll" />
                    <geom type="cylinder" size="0.3 0.1" material="wheel_material" mass="30" friction="1 0.001 0.001" />
                </body>
                <body name="car1_wheel3" pos="-0.6 -0.5 -0.0625" zaxis="0 1 0">
                    <joint name="car1_wheel3_joint_roll" />
                    <geom type="cylinder" size="0.3 0.1" material="wheel_material" mass="30" friction="1 0.001 0.001" />
                </body>
                <body name="car1_wheel4" pos="-0.6 0.5 -0.0625" zaxis="0 1 0">
                    <joint name="car1_wheel4_joint_roll" />
                    <geom type="cylinder" size="0.3 0.1" material="wheel_material" mass="30" friction="1 0.001 0.001" />
                </body>
            </body>
        </body>
    </worldbody>
    <tendon>
        <fixed name="car1_back_wheels_tendon">
            <joint joint="car1_wheel3_joint_roll" coef="1000" />
            <joint joint="car1_wheel4_joint_roll" coef="1000" />
        </fixed>
    </tendon>
    <actuator>
        <motor name="car1_engine_power" tendon="car1_back_wheels_tendon" ctrlrange="-1 1" />
        <position name="car1_wheel1_angle" joint="car1_wheel1_joint_steer" kp="1000" ctrlrange="-0.7853981633974483 0.7853981633974483" />
        <position name="car1_wheel2_angle" joint="car1_wheel2_joint_steer" kp="1000" ctrlrange="-0.7853981633974483 0.7853981633974483" />
    </actuator>
</mujoco>